Workbook

Sheet Summary
A1: SteelForce Mobile — Test Execution Summary
A2: Counts read live from Execution_Results. Filter by Run ID in cell B3.
A3: Run ID | B3: EXEC-20261008-014
A5: Result | B5: Count
A6: Pass | B6: =COUNTIFS(Execution_Results!$A$2:$A$2000,$B$3,Execution_Results!$I$2:$I$2000,"Pass")
A7: Fail | B7: =COUNTIFS(Execution_Results!$A$2:$A$2000,$B$3,Execution_Results!$I$2:$I$2000,"Fail")
A8: Blocked | B8: =COUNTIFS(Execution_Results!$A$2:$A$2000,$B$3,Execution_Results!$I$2:$I$2000,"Blocked")
A9: Not Run | B9: =COUNTIFS(Execution_Results!$A$2:$A$2000,$B$3,Execution_Results!$I$2:$I$2000,"Not Run")
A10: Skipped | B10: =COUNTIFS(Execution_Results!$A$2:$A$2000,$B$3,Execution_Results!$I$2:$I$2000,"Skipped")
A12: Issue Source (failures) | B12: Count
A13: Mobile | B13: =COUNTIFS(Execution_Results!$A$2:$A$2000,$B$3,Execution_Results!$K$2:$K$2000,"Mobile",Execution_Results!$I$2:$I$2000,"Fail")
A14: Backend | B14: =COUNTIFS(Execution_Results!$A$2:$A$2000,$B$3,Execution_Results!$K$2:$K$2000,"Backend",Execution_Results!$I$2:$I$2000,"Fail")
A15: Database | B15: =COUNTIFS(Execution_Results!$A$2:$A$2000,$B$3,Execution_Results!$K$2:$K$2000,"Database",Execution_Results!$I$2:$I$2000,"Fail")
A16: SAP | B16: =COUNTIFS(Execution_Results!$A$2:$A$2000,$B$3,Execution_Results!$K$2:$K$2000,"SAP",Execution_Results!$I$2:$I$2000,"Fail")
A17: Network | B17: =COUNTIFS(Execution_Results!$A$2:$A$2000,$B$3,Execution_Results!$K$2:$K$2000,"Network",Execution_Results!$I$2:$I$2000,"Fail")
A18: Test Data | B18: =COUNTIFS(Execution_Results!$A$2:$A$2000,$B$3,Execution_Results!$K$2:$K$2000,"Test Data",Execution_Results!$I$2:$I$2000,"Fail")
A19: Environment | B19: =COUNTIFS(Execution_Results!$A$2:$A$2000,$B$3,Execution_Results!$K$2:$K$2000,"Environment",Execution_Results!$I$2:$I$2000,"Fail")
A20: Unknown | B20: =COUNTIFS(Execution_Results!$A$2:$A$2000,$B$3,Execution_Results!$K$2:$K$2000,"Unknown",Execution_Results!$I$2:$I$2000,"Fail")
A21: Automation | B21: =COUNTIFS(Execution_Results!$A$2:$A$2000,$B$3,Execution_Results!$K$2:$K$2000,"Automation",Execution_Results!$I$2:$I$2000,"Fail")
A23: Assigned Team (failures) | B23: Count
A24: Mobile | B24: =COUNTIFS(Execution_Results!$A$2:$A$2000,$B$3,Execution_Results!$V$2:$V$2000,"Mobile",Execution_Results!$I$2:$I$2000,"Fail")
A25: Backend | B25: =COUNTIFS(Execution_Results!$A$2:$A$2000,$B$3,Execution_Results!$V$2:$V$2000,"Backend",Execution_Results!$I$2:$I$2000,"Fail")
A26: QA | B26: =COUNTIFS(Execution_Results!$A$2:$A$2000,$B$3,Execution_Results!$V$2:$V$2000,"QA",Execution_Results!$I$2:$I$2000,"Fail")
A27: SAP | B27: =COUNTIFS(Execution_Results!$A$2:$A$2000,$B$3,Execution_Results!$V$2:$V$2000,"SAP",Execution_Results!$I$2:$I$2000,"Fail")
A28: DevOps | B28: =COUNTIFS(Execution_Results!$A$2:$A$2000,$B$3,Execution_Results!$V$2:$V$2000,"DevOps",Execution_Results!$I$2:$I$2000,"Fail")
A30: Failures still missing triage | B30: =COUNTIFS(Execution_Results!$A$2:$A$2000,$B$3,Execution_Results!$I$2:$I$2000,"Fail")-COUNTIFS(Execution_Results!$A$2:$A$2000,$B$3,Execution_Results!$Y$2:$Y$2000,"OK",Execution_Results!$I$2:$I$2000,"Fail")

Sheet Test_Cases
A1: TC ID | B1: Module | C1: Feature | D1: Title | E1: Priority | F1: Test Type | G1: Preconditions | H1: Test Data | I1: Steps | J1: Expected Result | K1: API Endpoint | L1: Layers Exercised | M1: If It Fails — Check First | N1: Evidence to Capture | O1: Code Reference | P1: Automation Status | Q1: Suites | R1: Environments
A2: TC-AUTH-001 | B2: Authentication | C2: Login | D2: Login form validates before any request | E2: P1 | F2: Negative | G2: App on /login. | I2: 1. Leave phone empty, tap Sign in. 2. Enter phone, password of 5 chars, tap Sign in. | J2: 1. Inline error auth.phone_required. 2. Inline error auth.password_too_short (minimum 6). No network request is made (no api.request log). | K2: — | L2: Mobile | M2: Any api.request logged → Mobile (validation bypassed). | N2: Screenshot (EN + KM where text changes); screen name; device/OS; app version. | O2: phone_number_field.dart:92-96; login_form.dart:149-151 | P2: Planned | Q2: uat
A3: TC-AUTH-002 | B3: Authentication | C3: Login | D3: Successful login lands on the main shell | E3: P1 | F3: Functional | G3: Online. TD-001 active. | H3: TD-001 | I3: 1. Enter phone + password from the secret store. 2. Tap Sign in, then tap it again quickly. | J3: Spinner shows; the second tap is ignored. Tokens saved, profile read, back stack cleared, app opens /main with 4 tabs. | K3: POST /api/v1/mobile/auth/login → GET /api/v1/auth/me | L3: Mobile → Backend → DB | M3: Login 200 but /auth/me fails → see TC-AUTH-018. 401 with a known-good account → Backend. | N3: Screenshot; debug log lines api.request/api.response/api.error (method, path, status, errorCode, correlationId, dioType, host); timestamp. Mask tokens and phone numbers. | O3: auth_bloc.dart:136-182; auth_repository_impl.dart:46-127 | P3: Partial | Q3: smoke, regression, uat
A4: TC-AUTH-003 | B4: Authentication | C4: Login | D4: Login screen fits small phones, tablets and the keyboard | E4: P2 | F4: UI | G4: On /login. | I4: Open on a 360 dp phone, a tablet, both orientations; focus each field. | J4: No overflow; the focused field stays above the keyboard; Sign in reachable. | K4: — | L4: Mobile | N4: Screenshot (EN + KM where text changes); screen name; device/OS; app version. | O4: login_screen.dart | P4: Automated | Q4: regression, uat
A5: TC-AUTH-004 | B5: Authentication | C5: Login | D5: Wrong password shows the server message | E5: P1 | F5: Negative | G5: Online. TD-001. | H5: TD-001 | I5: Enter a wrong password once; tap Sign in. | J5: Red status pill with the server message (fallback “Your ID or password is incorrect.”). No automatic retry. No token refresh attempted. | K5: POST /api/v1/mobile/auth/login (expect 400/401 Auth.InvalidCredentials) | L5: Mobile → Backend | M5: Correct password refused → check account in portal (Test Data) before Backend. | N5: Screenshot; debug log lines api.request/api.response/api.error (method, path, status, errorCode, correlationId, dioType, host); timestamp. Mask tokens and phone numbers. | O5: auth_bloc.dart:175-179; auth_interceptor.dart:181-191 | P5: Partial | Q5: regression, uat
A6: TC-AUTH-005 | B6: Authentication | C6: Login | D6: Locked / inactive / expired-password accounts are refused with their message | E6: P1 | F6: Negative | G6: Online. TD-003, TD-004. | H6: TD-003, TD-004 | I6: Sign in with each account. | J6: Status pill shows the server text for Auth.AccountLocked / Auth.AccountInactive / Auth.PasswordExpired. User stays on /login. | K6: POST /api/v1/mobile/auth/login | L6: Mobile → Backend → DB | M6: Account state wrong in portal → Test Data. Right state, wrong errorCode → Backend. | N6: Screenshot; debug log lines api.request/api.response/api.error (method, path, status, errorCode, correlationId, dioType, host); timestamp. Mask tokens and phone numbers. | O6: auth_repository_impl.dart:340-348 | P6: Partial | Q6: regression, uat
A7: TC-AUTH-006 | B7: Authentication | C7: Login | D7: Login while offline | E7: P1 | F7: Offline | G7: Airplane mode on. | H7: TD-018 | I7: Enter valid credentials; tap Sign in. | J7: No request sent; message common.no_connection in the active language. | K7: — | L7: Mobile | M7: Shows server-unreachable instead → Mobile (interface check). Request logged → Mobile. | N7: Screenshot of the offline state; Sync Center / pending sheet before and after reconnect; api.* log lines after reconnect (correlationId). | O7: auth_repository_impl.dart:52-55; auth_bloc.dart:204-210 | P7: Planned | Q7: uat
A8: TC-AUTH-007 | B8: Authentication | C8: Login | D8: Login when UAT is unreachable / returns 5xx / times out | E8: P1 | F8: Negative | G8: Device online; UAT host blocked (wrong VPN) or backend down. | I8: Sign in with valid credentials. | J8: Unreachable or timeout → common.server_unreachable. 5xx → server message or “Something went wrong. Please try again.” No half-open session (tokens cleared). | K8: POST /api/v1/mobile/auth/login | L8: Mobile → Backend | M8: Use api.error `host` + dioType: wrong host → Environment; 5xx → Backend; receiveTimeout → Unknown until the correlationId is searched. | N8: Screenshot; debug log lines api.request/api.response/api.error (method, path, status, errorCode, correlationId, dioType, host); timestamp. Mask tokens and phone numbers. | O8: auth_repository_impl.dart:113-125 | P8: Planned | Q8: uat
A9: TC-AUTH-008 | B9: Authentication | C9: Temporary password | D9: Temporary-password policy | E9: P1 | F9: Negative | G9: TD-002 just reset (passwordChangeRequired = true). | H9: TD-002, TD-008 | I9: 1. Sign in → lands on /change-temporary-password. 2. Try 11 chars; same as current; mismatched confirm. | J9: auth.change_password_too_short (min 12), auth.change_password_same_as_current, auth.passwords_dont_match. Back is blocked; Sign out is the only exit. | K9: — | L9: Mobile | N9: Screenshot (EN + KM where text changes); screen name; device/OS; app version. | O9: change_temporary_password_screen.dart:41,94-102,163 | P9: Partial | Q9: smoke, regression, uat
A10: TC-AUTH-009 | B10: Authentication | C10: Temporary password | D10: Temporary password changed successfully | E10: P1 | F10: Functional | G10: TD-002 on /change-temporary-password. | H10: TD-002, TD-008 | I10: Enter a valid 12+ char password twice; submit. | J10: Change succeeds; app opens /main; next launch does not ask again. | K10: POST /api/v1/mobile/auth/change-password | L10: Mobile → Backend → DB | M10: 200 but the flag stays set on next login → Backend/Database. | N10: Screenshot; debug log lines api.request/api.response/api.error (method, path, status, errorCode, correlationId, dioType, host); timestamp. Mask tokens and phone numbers. | O10: auth_bloc.dart:186-197 | P10: Partial | Q10: regression, uat
A11: TC-AUTH-010 | B11: Authentication | C11: Temporary password | D11: Pending temporary password survives an app restart | E11: P1 | F11: Functional | G11: TD-002 signed in, change not done. | H11: TD-002 | I11: Kill the app; relaunch. | J11: Splash routes to /change-temporary-password and shows the current-password field (nothing carried over). | K11: — | L11: Mobile | N11: Screenshot (EN + KM where text changes); screen name; device/OS; app version. | O11: splash_screen.dart:71-76 | P11: Partial | Q11: regression, uat
A12: TC-AUTH-011 | B12: Authentication | C12: Forgot password | D12: Request SMS code (anti-enumeration) | E12: P1 | F12: Functional | G12: Signed out, on /forgot-password. | H12: TD-006, TD-007 | I12: 1. Submit empty phone. 2. Submit TD-006. 3. Submit TD-007. | J12: 1. Phone required. 2 & 3. Both report success and open /verify-otp (server answers 200 either way). Only TD-006 receives an SMS. | K12: POST /api/v1/auth/forgot-password/request | L12: Mobile → Backend | M12: No SMS to a registered number with 200 → Backend/SMS gateway (Environment). | N12: Screenshot; debug log lines api.request/api.response/api.error (method, path, status, errorCode, correlationId, dioType, host); timestamp. Mask tokens and phone numbers. | O12: forgot_password_screen.dart:44-81 | P12: Automated | Q12: regression, uat
A13: TC-AUTH-012 | B13: Authentication | C13: Forgot password | D13: Verify OTP: incomplete, paste, wrong code | E13: P1 | F13: Negative | G13: On /verify-otp for TD-006. | H13: TD-006 | I13: 1. Type 5 digits. 2. Paste “12 34-56”. 3. Enter a wrong 6-digit code. 4. Enter the real code. | J13: 1. auth.otp_incomplete. 2. Digits only kept, auto-submits. 3. Server message or auth.invalid_code; fields cleared. 4. Opens /create-new-password. | K13: POST /api/v1/auth/forgot-password/verify-otp | L13: Mobile → Backend | M13: 200 without resetToken is treated as an error by the app → Backend. | N13: Screenshot; debug log lines api.request/api.response/api.error (method, path, status, errorCode, correlationId, dioType, host); timestamp. Mask tokens and phone numbers. | O13: verify_screen.dart:82-108; otp_field.dart:46-76 | P13: Partial | Q13: regression, uat
A14: TC-AUTH-013 | B14: Authentication | C14: Forgot password | D14: Resend code cooldown and blocked/expired codes | E14: P2 | F14: Negative | G14: On /verify-otp. | H14: TD-006 | I14: 1. Tap Resend. 2. Wait for an expired code / exceed resend limit. | J14: 1. Resend disabled for 30 s (auth.resend_code_in). 2. Server message shown; user stays on screen (no dedicated handling for Auth.VerificationBlocked/Expired/ResendLimitReached). | K14: POST /api/v1/auth/forgot-password/request | L14: Mobile → Backend | M14: Known: resend failure is ignored and the cooldown restarts anyway (verify_screen.dart:111-121) → Mobile. | N14: Screenshot; debug log lines api.request/api.response/api.error (method, path, status, errorCode, correlationId, dioType, host); timestamp. Mask tokens and phone numbers. | O14: verify_screen.dart:29-30,111-121 | P14: Planned | Q14: uat
A15: TC-AUTH-014 | B15: Authentication | C15: Forgot password | D15: New password checked against the server policy | E15: P1 | F15: Negative | G15: On /create-new-password with a valid grant. | H15: TD-008 | I15: Try passwords violating min, max, uppercase, lowercase, number, special in turn; then a mismatched confirm. | J15: Errors in order: auth.password_min_length, _max_length, _needs_* ; confirm mismatch error. | K15: — | L15: Mobile | N15: Screenshot (EN + KM where text changes); screen name; device/OS; app version. | O15: create_new_password_screen.dart:84-99; password_reset_grant.dart:47-62 | P15: Automated | Q15: regression, uat
A16: TC-AUTH-015 | B16: Authentication | C16: Forgot password | D16: Reset succeeds and returns to login | E16: P1 | F16: Functional | G16: Valid password on /create-new-password. | H16: TD-006, TD-008 | I16: Submit; tap Back to login; sign in with the new password. | J16: /reset-password-success then /login with stack cleared; login works; other sessions are signed out. | K16: POST /api/v1/auth/forgot-password/reset | L16: Mobile → Backend → DB | M16: Reset 200 but old password still works → Backend. | N16: Screenshot; debug log lines api.request/api.response/api.error (method, path, status, errorCode, correlationId, dioType, host); timestamp. Mask tokens and phone numbers. | O16: app_page.dart:149-226 | P16: Planned | Q16: uat
A17: TC-AUTH-016 | B17: Authentication | C17: Login | D17: Remember me keeps the phone, never the password | E17: P2 | F17: Functional | G17: On /login. | H17: TD-001 | I17: Tick Remember me; sign in; sign out; relaunch. Then untick and repeat. | J17: Phone pre-filled, password empty. Unticked → phone forgotten. | K17: — | L17: Mobile | N17: Screenshot (EN + KM where text changes); screen name; device/OS; app version. | O17: login_screen.dart:61-69 | P17: Automated | Q17: regression, uat
A18: TC-AUTH-017 | B18: Authentication | C18: Guest | D18: Continue as guest | E18: P2 | F18: Functional | G18: On /login from first launch. | I18: Tap Continue as guest. | J18: Guest home with no app bar; any work area asks to sign in. | K18: — | L18: Mobile | N18: Screenshot (EN + KM where text changes); screen name; device/OS; app version. | O18: login_screen.dart:98-105 | P18: Automated | Q18: regression, uat
A19: TC-AUTH-018 | B19: Authentication | C19: Login | D19: Profile read fails right after login | E19: P2 | F19: Negative | G19: Login succeeds; GET /auth/me fails (e.g. backend 500). | I19: Sign in. | J19: Tokens wiped; failure shown; user stays signed out. | K19: GET /api/v1/auth/me | L19: Mobile → Backend | M19: Login 200 + /auth/me 5xx → Backend. | N19: Screenshot; debug log lines api.request/api.response/api.error (method, path, status, errorCode, correlationId, dioType, host); timestamp. Mask tokens and phone numbers. | O19: auth_repository_impl.dart:119-123 | P19: Automated | Q19: regression, uat
A20: TC-AUTH-019 | B20: Authentication | C20: Login | D20: Five wrong passwords lock the account (backend rule) | E20: P2 | F20: Security | G20: Throwaway account. | I20: Enter a wrong password 5 times. | J20: Account locked; message Auth.AccountLocked. App never retries on its own. | K20: POST /api/v1/mobile/auth/login | L20: Mobile → Backend → DB | M20: Lockout is server-side (comment auth_bloc.dart:173) → a missing lock is Backend. | N20: Screenshot; debug log lines api.request/api.response/api.error (method, path, status, errorCode, correlationId, dioType, host); timestamp. Mask tokens and phone numbers. | O20: auth_bloc.dart:173 | P20: Planned | Q20: uat
A21: TC-AUTH-020 | B21: Authentication | C21: Forgot password | D21: Offline error in the reset flow is shown in Khmer | E21: P2 | F21: Localization | G21: Khmer; airplane mode. | I21: Forgot password → submit a phone. | J21: Message in Khmer. CURRENT CODE shows English “No internet connection.” (f.message shown as-is). | K21: — | L21: Mobile | M21: English text → Mobile (app_page.dart:139,165,245). | N21: Screenshot (EN + KM where text changes); screen name; device/OS; app version. | O21: app_page.dart:139,165,245 | P21: Planned | Q21: uat
A22: TC-SES-001 | B22: Session | C22: Restore | D22: Signed-in rep reopens the app offline | E22: P1 | F22: Offline | G22: TD-001 signed in; airplane mode. | H22: TD-001 | I22: Kill and relaunch. | J22: Opens signed in from the cached profile; no network call needed. | K22: — | L22: Mobile | N22: Screenshot of the offline state; Sync Center / pending sheet before and after reconnect; api.* log lines after reconnect (correlationId). | O22: auth_repository_impl.dart:142-182 | P22: Planned | Q22: uat
A23: TC-SES-002 | B23: Session | C23: Token refresh | D23: Expired access token refreshes once and replays | E23: P1 | F23: API | G23: Signed in; wait > 15 min (access token lifetime 899 s). | I23: Open any list that calls the API. | J23: One POST refresh-token; original request replayed; screen loads. Parallel 401s share one refresh. | K23: POST /api/v1/mobile/auth/refresh-token | L23: Mobile → Backend | M23: Refresh 400 after a single legitimate rotation → Backend. Two refreshes in parallel → Mobile. | N23: Screenshot; debug log lines api.request/api.response/api.error (method, path, status, errorCode, correlationId, dioType, host); timestamp. Mask tokens and phone numbers. | O23: auth_interceptor.dart:97-151,226-271 | P23: Automated | Q23: smoke, regression, uat
A24: TC-SES-003 | B24: Session | C24: Token refresh | D24: 403 never signs the rep out | E24: P1 | F24: Security | G24: Signed in as a role without one permission. | I24: Open the forbidden area. | J24: “You do not have access to this action.”; no refresh, no sign-out. | K24: any → 403 | L24: Mobile → Backend | N24: Screenshot; debug log lines api.request/api.response/api.error (method, path, status, errorCode, correlationId, dioType, host); timestamp. Mask tokens and phone numbers. | O24: auth_interceptor.dart:181-186 | P24: Automated | Q24: regression, uat
A25: TC-SES-004 | B25: Session | C25: Token refresh | D25: Refresh rejected ends the session | E25: P1 | F25: Security | G25: Signed in; revoke the session in the portal. | I25: Trigger any API call after expiry. | J25: Tokens cleared; protected calls answer “Your session expired. Please sign in again.” | K25: POST /api/v1/mobile/auth/refresh-token → 400/401 | L25: Mobile → Backend | M25: Known gap: nothing navigates to login on expiry — user stays on screen while calls fail (TC-SES-009). | N25: Screenshot; debug log lines api.request/api.response/api.error (method, path, status, errorCode, correlationId, dioType, host); timestamp. Mask tokens and phone numbers. | O25: auth_interceptor.dart:132-137; session_manager.dart:182-188 | P25: Automated | Q25: smoke, regression, uat
A26: TC-SES-005 | B26: Session | C26: Sign out | D26: Sign-out blocked while work is unsent | E26: P1 | F26: Functional | G26: Offline; one unsynced check-in or depot. | H26: TD-001 | I26: Profile → Log out. | J26: Unsent-work dialog with the count; Open Sync Center opens the pending sheet; sign-out continues only when nothing is left. | K26: — | L26: Mobile | N26: Screenshot of the offline state; Sync Center / pending sheet before and after reconnect; api.* log lines after reconnect (correlationId). | O26: profile_screen.dart:58-96; auth_bloc.dart:248-254 | P26: Automated | Q26: smoke, regression, uat
A27: TC-SES-006 | B27: Session | C27: Sign out | D27: A different rep signing in wipes local data | E27: P1 | F27: Security | G27: TD-001 signed in with synced data. | H27: TD-001, TD-005 | I27: Sign out; sign in as TD-005. | J27: No depots, visits or orders of TD-001 visible. Same rep signing back in keeps data. | K27: — | L27: Mobile | N27: Screenshot (EN + KM where text changes); screen name; device/OS; app version. | O27: auth_bloc.dart:310-321 | P27: Automated | Q27: regression, uat
A28: TC-SES-007 | B28: Session | C28: Sign out | D28: Sign-out deregisters push and revokes the session | E28: P1 | F28: Security | G28: Online, nothing unsent. | I28: Profile → Log out → confirm. Send a push to TD-001 afterwards. | J28: Device DELETE before token clear; server logout fire-and-forget; app restarts as guest; no push arrives. | K28: DELETE /api/v1/mobile/devices/{id}; POST /api/v1/auth/logout | L28: Mobile → Backend → DB | M28: Push still arrives after a 2xx DELETE → Backend. | N28: Screenshot; debug log lines api.request/api.response/api.error (method, path, status, errorCode, correlationId, dioType, host); timestamp. Mask tokens and phone numbers. | O28: auth_bloc.dart:270-305 | P28: Automated | Q28: regression, uat
A29: TC-SES-008 | B29: Session | C29: Token refresh | D29: Transient refresh failure keeps the session | E29: P2 | F29: Offline | G29: Access token expired; go offline. | I29: Open a list. | J29: Request fails as a network error; rep is NOT signed out; works again when online. | K29: — | L29: Mobile | N29: Screenshot of the offline state; Sync Center / pending sheet before and after reconnect; api.* log lines after reconnect (correlationId). | O29: auth_interceptor.dart:139-150 | P29: Automated | Q29: regression, uat
A30: TC-SES-009 | B30: Session | C30: Session expiry | D30: What the rep sees after the session expires | E30: P1 | F30: UI | G30: Session revoked server-side. | I30: Use the app for 2 minutes. | J30: EXPECTED BY BUSINESS (to confirm): rep is taken to login. CURRENT CODE: stays on screen, calls fail with the expiry message. | K30: — | L30: Mobile → Backend | M30: If no redirect → Mobile (no listener on sessionExpired navigates). | N30: Screenshot (EN + KM where text changes); screen name; device/OS; app version. | O30: protected_feature.dart:89-103; session_manager.dart | P30: Planned | Q30: uat
A31: TC-SES-010 | B31: Session | C31: Session reset | D31: Sign-out clears every rep-scoped store | E31: P1 | F31: Security | G31: Signed in with depots, visits, quotations cached. | I31: Sign out; sign in as guest; open each tab. | J31: No previous rep data anywhere; session stores reset. | K31: — | L31: Mobile | N31: Screenshot (EN + KM where text changes); screen name; device/OS; app version. | P31: Automated | Q31: regression, uat
A32: TC-PRO-001 | B32: Profile | C32: Profile | D32: Profile loads and falls back to the cache | E32: P1 | F32: Functional | G32: Signed in. | H32: TD-001 | I32: 1. Open profile online. 2. Go offline; reopen. | J32: 1. Server profile (name, Khmer name, employee code, line manager). 2. Cached profile; no error. | K32: GET /api/v1/mobile/auth/profile | L32: Mobile → Backend → DB | N32: Screenshot; debug log lines api.request/api.response/api.error (method, path, status, errorCode, correlationId, dioType, host); timestamp. Mask tokens and phone numbers. | O32: auth_backed_profile_data_source.dart:67-93 | P32: Automated | Q32: smoke, regression, uat
A33: TC-PRO-002 | B33: Profile | C33: Profile | D33: Guest tapping the avatar is asked to sign in | E33: P1 | F33: Functional | G33: Guest. | I33: Tap the avatar. | J33: LoginRequiredDialog. | K33: — | L33: Mobile | N33: Screenshot (EN + KM where text changes); screen name; device/OS; app version. | O33: main_shell.dart:147-149 | P33: Partial | Q33: regression, uat
A34: TC-PRO-003 | B34: Profile | C34: Photo | D34: Upload, replace and remove the profile photo | E34: P2 | F34: Functional | G34: Signed in, online. | H34: TD-019 | I34: Pick a photo; save. Replace it. Remove it. | J34: Photo shown upright; GPS/EXIF stripped before upload; removal returns to initials. | K34: POST|DELETE /api/v1/users/profile-photo | L34: Mobile → Backend → DB | N34: Screenshot; debug log lines api.request/api.response/api.error (method, path, status, errorCode, correlationId, dioType, host); timestamp. Mask tokens and phone numbers. | O34: edit_profile_sheet.dart:170-189; profile_repository_impl.dart:23-34 | P34: Automated | Q34: regression, uat
A35: TC-PRO-004 | B35: Profile | C35: Photo | D35: Photo errors are explained | E35: P2 | F35: Negative | G35: Signed in. | H35: TD-019 | I35: Upload while offline; upload a file the server refuses by size / type. | J35: profile.error_offline; error_photo_size (413); error_photo_type (400); error_too_many (429); no change → profile.no_changes. | K35: POST /api/v1/users/profile-photo | L35: Mobile → Backend | M35: Map by HTTP status: 413/400 with a valid JPG < 5 MB → Backend. | N35: Screenshot; debug log lines api.request/api.response/api.error (method, path, status, errorCode, correlationId, dioType, host); timestamp. Mask tokens and phone numbers. | O35: edit_profile_sheet.dart:392-415 | P35: Automated | Q35: regression, uat
A36: TC-PRO-005 | B36: Profile | C36: Password | D36: Change password tile opens the SMS reset flow | E36: P2 | F36: Functional | G36: Signed in. | I36: Profile → Change password. | J36: Opens /forgot-password (SMS reset), not the change-password form. | K36: — | L36: Mobile | N36: Screenshot (EN + KM where text changes); screen name; device/OS; app version. | O36: profile_screen.dart:139-144 | P36: Planned | Q36: uat
A37: TC-PRO-006 | B37: Profile | C37: Profile | D37: Profile details: Khmer name, line manager, temporary-password expiry | E37: P3 | F37: Functional | G37: Signed in; profile has Khmer name and a line manager. | I37: Open profile in English and Khmer. | J37: Each field shown when present, hidden when absent; expiry shown only for a temporary password. | K37: — | L37: Mobile | N37: Screenshot (EN + KM where text changes); screen name; device/OS; app version. | P37: Automated | Q37: regression, uat

Sheet Test_Scenarios
A1: Scenario ID | B1: Module | C1: Scenario | D1: End-to-End Flow | E1: Linked TCs | F1: Priority | G1: Layers Exercised | H1: Notes
A2: SC-AUTH-01 | B2: Authentication | C2: First sign-in of a new rep with a temporary password | D2: Install → splash → language → onboarding → login (TD-002) → forced change-password (policy errors, then valid) → main shell → relaunch lands on main | E2: TC-AUTH-001, TC-AUTH-002, TC-AUTH-008, TC-AUTH-009, TC-AUTH-010 | F2: P1 | G2: Mobile → Backend → DB
A3: SC-AUTH-02 | B3: Authentication | C3: Daily sign-in, including a wrong password | D3: Login with a wrong password → error pill → correct password → main shell → Remember me pre-fills next time | E3: TC-AUTH-004, TC-AUTH-002, TC-AUTH-016 | F3: P1 | G3: Mobile → Backend → DB
A4: SC-AUTH-03 | B4: Authentication | C4: Forgotten password reset by SMS | D4: Login → Forgot? → phone → SMS code (wrong once, then right) → new password vs policy → success → login with new password | E4: TC-AUTH-011, TC-AUTH-012, TC-AUTH-013, TC-AUTH-014, TC-AUTH-015 | F4: P1 | G4: Mobile → Backend → SMS gateway | H4: SMS not received with HTTP 200 → Backend/SMS gateway (Environment), never Mobile.
A5: SC-AUTH-04 | B5: Authentication | C5: Sign-in when things go wrong | D5: Airplane mode → offline message; wrong VPN/host → server unreachable; locked and inactive accounts refused; 5 wrong passwords lock | E5: TC-AUTH-005, TC-AUTH-006, TC-AUTH-007, TC-AUTH-018, TC-AUTH-019 | F5: P1 | G5: Mobile → Network → Backend | H5: Use api.error host + dioType to separate Network / Environment / Backend.
A6: SC-SES-01 | B6: Session | C6: A full working day on one session | D6: Sign in → work offline → relaunch offline (still signed in) → back online after > 15 min (token refresh replays) → 403 area does not sign out | E6: TC-SES-001, TC-SES-002, TC-SES-003, TC-SES-008 | F6: P1 | G6: Mobile → Backend
A7: SC-SES-02 | B7: Session | C7: Session revoked by an admin | D7: Admin revokes session → next call refresh rejected → expiry message → (business to confirm) redirect to login | E7: TC-SES-004, TC-SES-009 | F7: P1 | G7: Mobile → Backend
A8: SC-SES-03 | B8: Session | C8: Handing the phone to another rep | D8: Offline work pending → logout blocked → Sync Center → sync → logout (push deregistered, session revoked) → second rep signs in → no data of first rep | E8: TC-SES-005, TC-SES-007, TC-SES-006, TC-SES-010 | F8: P1 | G8: Mobile → Backend → DB
A9: SC-PRO-01 | B9: Profile | C9: Rep reviews and updates their profile | D9: Open profile online → details correct → upload photo → replace → remove → errors for too-large / wrong type → offline shows cached profile | E9: TC-PRO-001, TC-PRO-003, TC-PRO-004, TC-PRO-006 | F9: P2 | G9: Mobile → Backend → Storage
A10: SC-PRO-02 | B10: Profile | C10: Guest and password entry points | D10: Guest taps avatar → sign-in prompt; signed in → Change password opens SMS reset | E10: TC-PRO-002, TC-PRO-005 | F10: P2 | G10: Mobile

Sheet Test_Data
A1: Data ID | B1: Description | C1: Category | D1: Value / Where to Get It | E1: Environment | F1: Used By | G1: Notes
A2: TD-001 | B2: Active field rep (primary test user) | C2: Account | D2: UAT secret store → QA_REP_PRIMARY (ask the QA lead). Never type the password into this workbook. | E2: UAT | F2: All signed-in TCs | G2: Needs at least one synced record for the sign-out / rep-switch cases.
A3: TD-002 | B3: Rep with a temporary password (passwordChangeRequired = true) | C3: Account | D3: Reset in the admin portal before each run; secret store → QA_REP_TEMP_PW | E3: UAT | F3: TC-AUTH-008..010
A4: TD-003 | B4: Locked account (Auth.AccountLocked) | C4: Account | D4: Admin portal → lock user QA_REP_LOCKED | E4: UAT | F4: TC-AUTH-005
A5: TD-004 | B5: Inactive account (Auth.AccountInactive) | C5: Account | D5: Admin portal → deactivate user QA_REP_INACTIVE | E5: UAT | F5: TC-AUTH-005
A6: TD-005 | B6: Second rep (for rep-switch wipe) | C6: Account | D6: Secret store → QA_REP_SECONDARY | E6: UAT | F6: TC-SES-006
A7: TD-006 | B7: Registered phone that receives the reset SMS | C7: Phone | D7: QA team handset — number held by the QA lead | E7: UAT | F7: TC-AUTH-011..014
A8: TD-007 | B8: Unregistered but well-formed phone number | C8: Phone | D8: Any number not in UAT (server still answers 200) | E8: UAT | F8: TC-AUTH-011
A9: TD-008 | B9: Candidate new passwords for policy checks | C9: Password | D9: Generate per run: 11 chars; 12+ chars; no uppercase; no digit; no special; same as current | E9: UAT | F9: TC-AUTH-008, TC-AUTH-014 | G9: Use throwaway values; do not reuse a real password.
A10: TD-018 | B10: Network conditions | C10: Device | D10: Airplane mode; Android emulator network throttling / iOS Network Link Conditioner (100% loss, 3G) | E10: UAT | F10: TC-AUTH-006, TC-SES-001, TC-SES-008
A11: TD-019 | B11: Photos for depot registration | C11: Media | D11: Photos taken at test time: one normal JPG; one > 5 MB; one .gif | E11: UAT | F11: TC-PRO-003, TC-PRO-004

Sheet Automation_Mapping
A1: TC ID | B1: Title | C1: Automation Status | D1: Automation Level | E1: Existing Test File | F1: Gap / Next Automation Step | G1: Automation ID
A2: TC-AUTH-001 | B2: Login form validates before any request | C2: Planned | D2: Manual | E2: — | F2: Widget test for both validators. | G2: manual
A3: TC-AUTH-002 | B3: Successful login lands on the main shell | C3: Partial | D3: Unit | E3: test/features/authentication/login_no_otp_test.dart; test/features/authentication/auth_me_profile_test.dart | F3: E2E device test with a UAT account. | G3: flutter:test/features/authentication/login_no_otp_test.dart; flutter:test/features/authentication/auth_me_profile_test.dart; pytest:tests/api/test_auth.py::test_login_returns_a_usable_token_pair; pytest:tests/api/test_auth.py::test_current_user_matches_the_contract; drive:integration_test/auth/login_device_test.dart
A4: TC-AUTH-003 | B4: Login screen fits small phones, tablets and the keyboard | C4: Automated | D4: Widget | E4: test/features/authentication/login_screen_layout_test.dart; test/features/authentication/login_keyboard_test.dart; test/features/authentication/login_keyboard_insets_test.dart | G4: flutter:test/features/authentication/login_screen_layout_test.dart; flutter:test/features/authentication/login_keyboard_test.dart; flutter:test/features/authentication/login_keyboard_insets_test.dart
A5: TC-AUTH-004 | B5: Wrong password shows the server message | C5: Partial | D5: Unit | E5: test/features/authentication/auth_failure_mapping_test.dart | F5: Widget test for the status pill. | G5: flutter:test/features/authentication/auth_failure_mapping_test.dart; pytest:tests/api/test_auth.py::test_a_wrong_password_is_refused_without_tokens
A6: TC-AUTH-005 | B6: Locked / inactive / expired-password accounts are refused with their message | C6: Partial | D6: E2E (device) | E6: integration_test/auth/account_state_refused_device_test.dart | F6: Device test injects each refusal (documented and staging shapes). Still needed: real locked / inactive / expired accounts on UAT (TD-003, TD-004) to confirm the backend's own codes. | G6: drive:integration_test/auth/account_state_refused_device_test.dart
A7: TC-AUTH-006 | B7: Login while offline | C7: Planned | D7: Manual | E7: — | F7: Repository unit test with an offline NetworkInfo fake; widget test for the translated message. | G7: manual
A8: TC-AUTH-007 | B8: Login when UAT is unreachable / returns 5xx / times out | C8: Planned | D8: Manual | E8: — | F8: Repository unit tests for unreachable, 5xx and timeout (tokens cleared). | G8: manual
A9: TC-AUTH-008 | B9: Temporary-password policy | C9: Partial | D9: Widget | E9: test/features/authentication/temporary_password_test.dart | F9: Widget test for the server-failure message on submit. | G9: flutter:test/features/authentication/temporary_password_test.dart
A10: TC-AUTH-009 | B10: Temporary password changed successfully | C10: Partial | D10: Widget | E10: test/features/authentication/temporary_password_test.dart | F10: Device E2E against UAT (needs an account reset per run). | G10: flutter:test/features/authentication/temporary_password_test.dart
A11: TC-AUTH-010 | B11: Pending temporary password survives an app restart | C11: Partial | D11: Unit | E11: test/features/authentication/temporary_password_test.dart | F11: Splash routing test. | G11: flutter:test/features/authentication/temporary_password_test.dart
A12: TC-AUTH-011 | B12: Request SMS code (anti-enumeration) | C12: Automated | D12: Widget | E12: test/features/authentication/forgot_password_flow_test.dart | G12: flutter:test/features/authentication/forgot_password_flow_test.dart
A13: TC-AUTH-012 | B13: Verify OTP: incomplete, paste, wrong code | C13: Partial | D13: Unit | E13: test/features/authentication/password_reset_by_phone_test.dart | F13: OTP screen widget test. | G13: flutter:test/features/authentication/password_reset_by_phone_test.dart
A14: TC-AUTH-013 | B14: Resend code cooldown and blocked/expired codes | C14: Planned | D14: Manual | E14: — | F14: OTP screen widget test: 30 s cooldown, resend failure handling. | G14: manual
A15: TC-AUTH-014 | B15: New password checked against the server policy | C15: Automated | D15: Widget | E15: test/features/authentication/create_new_password_policy_test.dart | G15: flutter:test/features/authentication/create_new_password_policy_test.dart
A16: TC-AUTH-015 | B16: Reset succeeds and returns to login | C16: Planned | D16: Manual | E16: — | F16: Keep manual — the SMS needs a real handset. | G16: manual
A17: TC-AUTH-016 | B17: Remember me keeps the phone, never the password | C17: Automated | D17: Unit | E17: test/features/authentication/remember_phone_test.dart | G17: flutter:test/features/authentication/remember_phone_test.dart
A18: TC-AUTH-017 | B18: Continue as guest | C18: Automated | D18: Widget | E18: test/features/shell/guest_home_screen_test.dart | G18: flutter:test/features/shell/guest_home_screen_test.dart
A19: TC-AUTH-018 | B19: Profile read fails right after login | C19: Automated | D19: E2E (device) | E19: integration_test/auth/profile_read_failure_device_test.dart | F19: Device test: real login on the backend, /auth/me answered 503 inside the test. Optional: a repository unit test for faster feedback. | G19: drive:integration_test/auth/profile_read_failure_device_test.dart
A20: TC-AUTH-019 | B20: Five wrong passwords lock the account (backend rule) | C20: Planned | D20: Manual | E20: — | F20: Manual only on mobile; the lockout rule belongs in backend API tests. | G20: manual
A21: TC-AUTH-020 | B21: Offline error in the reset flow is shown in Khmer | C21: Planned | D21: Manual | E21: — | F21: Widget test in km with a NetworkFailure on each reset step. | G21: manual
A22: TC-SES-001 | B22: Signed-in rep reopens the app offline | C22: Planned | D22: Manual | E22: — | F22: AuthBloc restore unit test. | G22: manual
A23: TC-SES-002 | B23: Expired access token refreshes once and replays | C23: Automated | D23: Unit | E23: test/core/network/auth_interceptor_test.dart | G23: flutter:test/core/network/auth_interceptor_test.dart; pytest:tests/api/test_auth.py::test_refresh_rotates_both_tokens_and_the_new_access_token_works; pytest:tests/api/test_auth.py::test_a_rotated_refresh_token_cannot_be_used_again
A24: TC-SES-003 | B24: 403 never signs the rep out | C24: Automated | D24: Unit | E24: test/core/network/auth_interceptor_test.dart | G24: flutter:test/core/network/auth_interceptor_test.dart
A25: TC-SES-004 | B25: Refresh rejected ends the session | C25: Automated | D25: Unit | E25: test/core/network/auth_interceptor_test.dart | G25: flutter:test/core/network/auth_interceptor_test.dart; pytest:tests/api/test_auth.py::test_refresh_with_an_unknown_token_is_refused; pytest:tests/api/test_auth.py::test_a_protected_route_without_a_token_is_401
A26: TC-SES-005 | B26: Sign-out blocked while work is unsent | C26: Automated | D26: Widget | E26: test/features/authentication/auth_logout_test.dart; test/features/profile/unsent_work_dialog_test.dart; test/core/session/unsent_work_order_test.dart | G26: flutter:test/features/authentication/auth_logout_test.dart; flutter:test/features/profile/unsent_work_dialog_test.dart; flutter:test/core/session/unsent_work_order_test.dart
A27: TC-SES-006 | B27: A different rep signing in wipes local data | C27: Automated | D27: Unit | E27: test/core/session/local_data_wipe_test.dart | G27: flutter:test/core/session/local_data_wipe_test.dart
A28: TC-SES-007 | B28: Sign-out deregisters push and revokes the session | C28: Automated | D28: Unit | E28: test/features/authentication/auth_repository_logout_test.dart | G28: flutter:test/features/authentication/auth_repository_logout_test.dart; pytest:tests/api/test_auth.py::test_logout_revokes_the_session
A29: TC-SES-008 | B29: Transient refresh failure keeps the session | C29: Automated | D29: Unit | E29: test/core/network/auth_interceptor_test.dart | G29: flutter:test/core/network/auth_interceptor_test.dart
A30: TC-SES-009 | B30: What the rep sees after the session expires | C30: Planned | D30: Manual | E30: — | F30: Decide the expected UX first, then a widget test. | G30: manual
A31: TC-SES-010 | B31: Sign-out clears every rep-scoped store | C31: Automated | D31: Unit | E31: test/core/session/session_reset_service_test.dart; test/core/session/session_manager_test.dart | G31: flutter:test/core/session/session_reset_service_test.dart; flutter:test/core/session/session_manager_test.dart
A32: TC-PRO-001 | B32: Profile loads and falls back to the cache | C32: Automated | D32: Unit | E32: test/features/profile/auth_backed_profile_test.dart | G32: flutter:test/features/profile/auth_backed_profile_test.dart; pytest:tests/api/test_auth.py::test_my_profile_matches_the_contract
A33: TC-PRO-002 | B33: Guest tapping the avatar is asked to sign in | C33: Partial | D33: Widget | E33: test/features/shell/guest_home_screen_test.dart | G33: flutter:test/features/shell/guest_home_screen_test.dart
A34: TC-PRO-003 | B34: Upload, replace and remove the profile photo | C34: Automated | D34: Unit | E34: test/features/profile/profile_update_test.dart | G34: flutter:test/features/profile/profile_update_test.dart
A35: TC-PRO-004 | B35: Photo errors are explained | C35: Automated | D35: Widget | E35: test/features/profile/profile_edit_ui_test.dart | G35: flutter:test/features/profile/profile_edit_ui_test.dart
A36: TC-PRO-005 | B36: Change password tile opens the SMS reset flow | C36: Planned | D36: Manual | E36: — | F36: Confirm with business that this is intended. | G36: manual
A37: TC-PRO-006 | B37: Profile details: Khmer name, line manager, temporary-password expiry | C37: Automated | D37: Widget | E37: test/features/profile/profile_details_fields_test.dart | G37: flutter:test/features/profile/profile_details_fields_test.dart

Sheet Execution_Results
A1: Run ID | B1: TC ID | C1: Executed On | D1: Executed By | E1: Environment | F1: App Version | G1: Device | H1: OS Version | I1: Test Result | J1: Issue Detected | K1: Issue Source | L1: Issue Type | M1: Error Message | N1: HTTP Status | O1: API Endpoint | P1: Correlation ID | Q1: errorCode / dioType | R1: Mobile Evidence | S1: Backend Evidence | T1: Root Cause | U1: Bug ID | V1: Assigned Team | W1: Confidence | X1: Notes | Y1: Triage Check
A2: AUTO-2026-10-08 | B2: TC-AUTH-002 | C2: 2026-10-08 | D2: Claude (flutter test) | E2: Local (unit/widget) | F2: 1.0.0+1 @ 644056f | G2: macOS host — flutter test | H2: n/a | I2: Pass | J2: No | R2: login_no_otp_test.dart: 2 passed; auth_me_profile_test.dart: 5 passed | X2: Automated part only — E2E device test with a UAT account. | Y2: =IF(I2="","",IF(AND(I2="Fail",K2=""),"Classify Issue Source",IF(AND(I2="Fail",W2=""),"Set Confidence",IF(AND(K2="Unknown",W2<>"Low"),"Unknown must be Low confidence",IF(AND(OR(K2="Backend",K2="SAP"),N2=""),"Add HTTP status + endpoint",IF(AND(OR(K2="Backend",K2="SAP",K2="Network"),P2=""),"Add Correlation ID",IF(AND(I2="Fail",T2=""),"Write Root Cause / evidence gap",IF(AND(I2="Fail",V2=""),"Assign team","OK"))))))))
A3: AUTO-2026-10-08 | B3: TC-AUTH-003 | C3: 2026-10-08 | D3: Claude (flutter test) | E3: Local (unit/widget) | F3: 1.0.0+1 @ 644056f | G3: macOS host — flutter test | H3: n/a | I3: Pass | J3: No | R3: login_screen_layout_test.dart: 15 passed; login_keyboard_test.dart: 3 passed; login_keyboard_insets_test.dart: 2 passed | X3: Automated coverage; still run once on a device against UAT. | Y3: =IF(I3="","",IF(AND(I3="Fail",K3=""),"Classify Issue Source",IF(AND(I3="Fail",W3=""),"Set Confidence",IF(AND(K3="Unknown",W3<>"Low"),"Unknown must be Low confidence",IF(AND(OR(K3="Backend",K3="SAP"),N3=""),"Add HTTP status + endpoint",IF(AND(OR(K3="Backend",K3="SAP",K3="Network"),P3=""),"Add Correlation ID",IF(AND(I3="Fail",T3=""),"Write Root Cause / evidence gap",IF(AND(I3="Fail",V3=""),"Assign team","OK"))))))))
A4: AUTO-2026-10-08 | B4: TC-AUTH-004 | C4: 2026-10-08 | D4: Claude (flutter test) | E4: Local (unit/widget) | F4: 1.0.0+1 @ 644056f | G4: macOS host — flutter test | H4: n/a | I4: Pass | J4: No | R4: auth_failure_mapping_test.dart: 1 passed | X4: Automated part only — Widget test for the status pill. | Y4: =IF(I4="","",IF(AND(I4="Fail",K4=""),"Classify Issue Source",IF(AND(I4="Fail",W4=""),"Set Confidence",IF(AND(K4="Unknown",W4<>"Low"),"Unknown must be Low confidence",IF(AND(OR(K4="Backend",K4="SAP"),N4=""),"Add HTTP status + endpoint",IF(AND(OR(K4="Backend",K4="SAP",K4="Network"),P4=""),"Add Correlation ID",IF(AND(I4="Fail",T4=""),"Write Root Cause / evidence gap",IF(AND(I4="Fail",V4=""),"Assign team","OK"))))))))
A5: AUTO-2026-10-08 | B5: TC-AUTH-008 | C5: 2026-10-08 | D5: Claude (flutter test) | E5: Local (unit/widget) | F5: 1.0.0+1 @ 644056f | G5: macOS host — flutter test | H5: n/a | I5: Pass | J5: No | R5: temporary_password_test.dart: 15 passed | X5: Automated part only — Widget test for the server-failure message on submit. | Y5: =IF(I5="","",IF(AND(I5="Fail",K5=""),"Classify Issue Source",IF(AND(I5="Fail",W5=""),"Set Confidence",IF(AND(K5="Unknown",W5<>"Low"),"Unknown must be Low confidence",IF(AND(OR(K5="Backend",K5="SAP"),N5=""),"Add HTTP status + endpoint",IF(AND(OR(K5="Backend",K5="SAP",K5="Network"),P5=""),"Add Correlation ID",IF(AND(I5="Fail",T5=""),"Write Root Cause / evidence gap",IF(AND(I5="Fail",V5=""),"Assign team","OK"))))))))
A6: AUTO-2026-10-08 | B6: TC-AUTH-009 | C6: 2026-10-08 | D6: Claude (flutter test) | E6: Local (unit/widget) | F6: 1.0.0+1 @ 644056f | G6: macOS host — flutter test | H6: n/a | I6: Pass | J6: No | R6: temporary_password_test.dart: 15 passed | X6: Automated part only — Device E2E against UAT (needs an account reset per run). | Y6: =IF(I6="","",IF(AND(I6="Fail",K6=""),"Classify Issue Source",IF(AND(I6="Fail",W6=""),"Set Confidence",IF(AND(K6="Unknown",W6<>"Low"),"Unknown must be Low confidence",IF(AND(OR(K6="Backend",K6="SAP"),N6=""),"Add HTTP status + endpoint",IF(AND(OR(K6="Backend",K6="SAP",K6="Network"),P6=""),"Add Correlation ID",IF(AND(I6="Fail",T6=""),"Write Root Cause / evidence gap",IF(AND(I6="Fail",V6=""),"Assign team","OK"))))))))
A7: AUTO-2026-10-08 | B7: TC-AUTH-010 | C7: 2026-10-08 | D7: Claude (flutter test) | E7: Local (unit/widget) | F7: 1.0.0+1 @ 644056f | G7: macOS host — flutter test | H7: n/a | I7: Pass | J7: No | R7: temporary_password_test.dart: 15 passed | X7: Automated part only — Splash routing test. | Y7: =IF(I7="","",IF(AND(I7="Fail",K7=""),"Classify Issue Source",IF(AND(I7="Fail",W7=""),"Set Confidence",IF(AND(K7="Unknown",W7<>"Low"),"Unknown must be Low confidence",IF(AND(OR(K7="Backend",K7="SAP"),N7=""),"Add HTTP status + endpoint",IF(AND(OR(K7="Backend",K7="SAP",K7="Network"),P7=""),"Add Correlation ID",IF(AND(I7="Fail",T7=""),"Write Root Cause / evidence gap",IF(AND(I7="Fail",V7=""),"Assign team","OK"))))))))
A8: AUTO-2026-10-08 | B8: TC-AUTH-011 | C8: 2026-10-08 | D8: Claude (flutter test) | E8: Local (unit/widget) | F8: 1.0.0+1 @ 644056f | G8: macOS host — flutter test | H8: n/a | I8: Pass | J8: No | R8: forgot_password_flow_test.dart: 1 passed | X8: Automated coverage; still run once on a device against UAT. | Y8: =IF(I8="","",IF(AND(I8="Fail",K8=""),"Classify Issue Source",IF(AND(I8="Fail",W8=""),"Set Confidence",IF(AND(K8="Unknown",W8<>"Low"),"Unknown must be Low confidence",IF(AND(OR(K8="Backend",K8="SAP"),N8=""),"Add HTTP status + endpoint",IF(AND(OR(K8="Backend",K8="SAP",K8="Network"),P8=""),"Add Correlation ID",IF(AND(I8="Fail",T8=""),"Write Root Cause / evidence gap",IF(AND(I8="Fail",V8=""),"Assign team","OK"))))))))
A9: AUTO-2026-10-08 | B9: TC-AUTH-012 | C9: 2026-10-08 | D9: Claude (flutter test) | E9: Local (unit/widget) | F9: 1.0.0+1 @ 644056f | G9: macOS host — flutter test | H9: n/a | I9: Pass | J9: No | R9: password_reset_by_phone_test.dart: 8 passed | X9: Automated part only — OTP screen widget test. | Y9: =IF(I9="","",IF(AND(I9="Fail",K9=""),"Classify Issue Source",IF(AND(I9="Fail",W9=""),"Set Confidence",IF(AND(K9="Unknown",W9<>"Low"),"Unknown must be Low confidence",IF(AND(OR(K9="Backend",K9="SAP"),N9=""),"Add HTTP status + endpoint",IF(AND(OR(K9="Backend",K9="SAP",K9="Network"),P9=""),"Add Correlation ID",IF(AND(I9="Fail",T9=""),"Write Root Cause / evidence gap",IF(AND(I9="Fail",V9=""),"Assign team","OK"))))))))
A10: AUTO-2026-10-08 | B10: TC-AUTH-014 | C10: 2026-10-08 | D10: Claude (flutter test) | E10: Local (unit/widget) | F10: 1.0.0+1 @ 644056f | G10: macOS host — flutter test | H10: n/a | I10: Pass | J10: No | R10: create_new_password_policy_test.dart: 3 passed | X10: Automated coverage; still run once on a device against UAT. | Y10: =IF(I10="","",IF(AND(I10="Fail",K10=""),"Classify Issue Source",IF(AND(I10="Fail",W10=""),"Set Confidence",IF(AND(K10="Unknown",W10<>"Low"),"Unknown must be Low confidence",IF(AND(OR(K10="Backend",K10="SAP"),N10=""),"Add HTTP status + endpoint",IF(AND(OR(K10="Backend",K10="SAP",K10="Network"),P10=""),"Add Correlation ID",IF(AND(I10="Fail",T10=""),"Write Root Cause / evidence gap",IF(AND(I10="Fail",V10=""),"Assign team","OK"))))))))
A11: AUTO-2026-10-08 | B11: TC-AUTH-016 | C11: 2026-10-08 | D11: Claude (flutter test) | E11: Local (unit/widget) | F11: 1.0.0+1 @ 644056f | G11: macOS host — flutter test | H11: n/a | I11: Pass | J11: No | R11: remember_phone_test.dart: 8 passed | X11: Automated coverage; still run once on a device against UAT. | Y11: =IF(I11="","",IF(AND(I11="Fail",K11=""),"Classify Issue Source",IF(AND(I11="Fail",W11=""),"Set Confidence",IF(AND(K11="Unknown",W11<>"Low"),"Unknown must be Low confidence",IF(AND(OR(K11="Backend",K11="SAP"),N11=""),"Add HTTP status + endpoint",IF(AND(OR(K11="Backend",K11="SAP",K11="Network"),P11=""),"Add Correlation ID",IF(AND(I11="Fail",T11=""),"Write Root Cause / evidence gap",IF(AND(I11="Fail",V11=""),"Assign team","OK"))))))))
A12: AUTO-2026-10-08 | B12: TC-SES-002 | C12: 2026-10-08 | D12: Claude (flutter test) | E12: Local (unit/widget) | F12: 1.0.0+1 @ 644056f | G12: macOS host — flutter test | H12: n/a | I12: Pass | J12: No | R12: auth_interceptor_test.dart: 17 passed | X12: Automated coverage; still run once on a device against UAT. | Y12: =IF(I12="","",IF(AND(I12="Fail",K12=""),"Classify Issue Source",IF(AND(I12="Fail",W12=""),"Set Confidence",IF(AND(K12="Unknown",W12<>"Low"),"Unknown must be Low confidence",IF(AND(OR(K12="Backend",K12="SAP"),N12=""),"Add HTTP status + endpoint",IF(AND(OR(K12="Backend",K12="SAP",K12="Network"),P12=""),"Add Correlation ID",IF(AND(I12="Fail",T12=""),"Write Root Cause / evidence gap",IF(AND(I12="Fail",V12=""),"Assign team","OK"))))))))
A13: AUTO-2026-10-08 | B13: TC-SES-003 | C13: 2026-10-08 | D13: Claude (flutter test) | E13: Local (unit/widget) | F13: 1.0.0+1 @ 644056f | G13: macOS host — flutter test | H13: n/a | I13: Pass | J13: No | R13: auth_interceptor_test.dart: 17 passed | X13: Automated coverage; still run once on a device against UAT. | Y13: =IF(I13="","",IF(AND(I13="Fail",K13=""),"Classify Issue Source",IF(AND(I13="Fail",W13=""),"Set Confidence",IF(AND(K13="Unknown",W13<>"Low"),"Unknown must be Low confidence",IF(AND(OR(K13="Backend",K13="SAP"),N13=""),"Add HTTP status + endpoint",IF(AND(OR(K13="Backend",K13="SAP",K13="Network"),P13=""),"Add Correlation ID",IF(AND(I13="Fail",T13=""),"Write Root Cause / evidence gap",IF(AND(I13="Fail",V13=""),"Assign team","OK"))))))))
... A23: AUTO-2026-10-08 | B23: TC-PRO-006 | C23: 2026-10-08 | D23: Claude (flutter test) | E23: Local (unit/widget) | F23: 1.0.0+1 @ 644056f | G23: macOS host — flutter test | H23: n/a | I23: Pass | J23: No | R23: profile_details_fields_test.dart: 11 passed | X23: Automated coverage; still run once on a device against UAT. | Y23: =IF(I23="","",IF(AND(I23="Fail",K23=""),"Classify Issue Source",IF(AND(I23="Fail",W23=""),"Set Confidence",IF(AND(K23="Unknown",W23<>"Low"),"Unknown must be Low confidence",IF(AND(OR(K23="Backend",K23="SAP"),N23=""),"Add HTTP status + endpoint",IF(AND(OR(K23="Backend",K23="SAP",K23="Network"),P23=""),"Add Correlation ID",IF(AND(I23="Fail",T23=""),"Write Root Cause / evidence gap",IF(AND(I23="Fail",V23=""),"Assign team","OK"))))))))
A24: UAT-R1 | B24: TC-AUTH-001 | I24: Not Run | Y24: =IF(I24="","",IF(AND(I24="Fail",K24=""),"Classify Issue Source",IF(AND(I24="Fail",W24=""),"Set Confidence",IF(AND(K24="Unknown",W24<>"Low"),"Unknown must be Low confidence",IF(AND(OR(K24="Backend",K24="SAP"),N24=""),"Add HTTP status + endpoint",IF(AND(OR(K24="Backend",K24="SAP",K24="Network"),P24=""),"Add Correlation ID",IF(AND(I24="Fail",T24=""),"Write Root Cause / evidence gap",IF(AND(I24="Fail",V24=""),"Assign team","OK"))))))))
A25: UAT-R1 | B25: TC-AUTH-002 | I25: Not Run | Y25: =IF(I25="","",IF(AND(I25="Fail",K25=""),"Classify Issue Source",IF(AND(I25="Fail",W25=""),"Set Confidence",IF(AND(K25="Unknown",W25<>"Low"),"Unknown must be Low confidence",IF(AND(OR(K25="Backend",K25="SAP"),N25=""),"Add HTTP status + endpoint",IF(AND(OR(K25="Backend",K25="SAP",K25="Network"),P25=""),"Add Correlation ID",IF(AND(I25="Fail",T25=""),"Write Root Cause / evidence gap",IF(AND(I25="Fail",V25=""),"Assign team","OK"))))))))
A26: UAT-R1 | B26: TC-AUTH-003 | I26: Not Run | Y26: =IF(I26="","",IF(AND(I26="Fail",K26=""),"Classify Issue Source",IF(AND(I26="Fail",W26=""),"Set Confidence",IF(AND(K26="Unknown",W26<>"Low"),"Unknown must be Low confidence",IF(AND(OR(K26="Backend",K26="SAP"),N26=""),"Add HTTP status + endpoint",IF(AND(OR(K26="Backend",K26="SAP",K26="Network"),P26=""),"Add Correlation ID",IF(AND(I26="Fail",T26=""),"Write Root Cause / evidence gap",IF(AND(I26="Fail",V26=""),"Assign team","OK"))))))))
A27: UAT-R1 | B27: TC-AUTH-004 | I27: Not Run | Y27: =IF(I27="","",IF(AND(I27="Fail",K27=""),"Classify Issue Source",IF(AND(I27="Fail",W27=""),"Set Confidence",IF(AND(K27="Unknown",W27<>"Low"),"Unknown must be Low confidence",IF(AND(OR(K27="Backend",K27="SAP"),N27=""),"Add HTTP status + endpoint",IF(AND(OR(K27="Backend",K27="SAP",K27="Network"),P27=""),"Add Correlation ID",IF(AND(I27="Fail",T27=""),"Write Root Cause / evidence gap",IF(AND(I27="Fail",V27=""),"Assign team","OK"))))))))
A28: UAT-R1 | B28: TC-AUTH-005 | I28: Not Run | Y28: =IF(I28="","",IF(AND(I28="Fail",K28=""),"Classify Issue Source",IF(AND(I28="Fail",W28=""),"Set Confidence",IF(AND(K28="Unknown",W28<>"Low"),"Unknown must be Low confidence",IF(AND(OR(K28="Backend",K28="SAP"),N28=""),"Add HTTP status + endpoint",IF(AND(OR(K28="Backend",K28="SAP",K28="Network"),P28=""),"Add Correlation ID",IF(AND(I28="Fail",T28=""),"Write Root Cause / evidence gap",IF(AND(I28="Fail",V28=""),"Assign team","OK"))))))))
A29: UAT-R1 | B29: TC-AUTH-006 | I29: Not Run | Y29: =IF(I29="","",IF(AND(I29="Fail",K29=""),"Classify Issue Source",IF(AND(I29="Fail",W29=""),"Set Confidence",IF(AND(K29="Unknown",W29<>"Low"),"Unknown must be Low confidence",IF(AND(OR(K29="Backend",K29="SAP"),N29=""),"Add HTTP status + endpoint",IF(AND(OR(K29="Backend",K29="SAP",K29="Network"),P29=""),"Add Correlation ID",IF(AND(I29="Fail",T29=""),"Write Root Cause / evidence gap",IF(AND(I29="Fail",V29=""),"Assign team","OK"))))))))
A30: UAT-R1 | B30: TC-AUTH-007 | I30: Not Run | Y30: =IF(I30="","",IF(AND(I30="Fail",K30=""),"Classify Issue Source",IF(AND(I30="Fail",W30=""),"Set Confidence",IF(AND(K30="Unknown",W30<>"Low"),"Unknown must be Low confidence",IF(AND(OR(K30="Backend",K30="SAP"),N30=""),"Add HTTP status + endpoint",IF(AND(OR(K30="Backend",K30="SAP",K30="Network"),P30=""),"Add Correlation ID",IF(AND(I30="Fail",T30=""),"Write Root Cause / evidence gap",IF(AND(I30="Fail",V30=""),"Assign team","OK"))))))))
A31: UAT-R1 | B31: TC-AUTH-008 | I31: Not Run | Y31: =IF(I31="","",IF(AND(I31="Fail",K31=""),"Classify Issue Source",IF(AND(I31="Fail",W31=""),"Set Confidence",IF(AND(K31="Unknown",W31<>"Low"),"Unknown must be Low confidence",IF(AND(OR(K31="Backend",K31="SAP"),N31=""),"Add HTTP status + endpoint",IF(AND(OR(K31="Backend",K31="SAP",K31="Network"),P31=""),"Add Correlation ID",IF(AND(I31="Fail",T31=""),"Write Root Cause / evidence gap",IF(AND(I31="Fail",V31=""),"Assign team","OK"))))))))
A32: UAT-R1 | B32: TC-AUTH-009 | I32: Not Run | Y32: =IF(I32="","",IF(AND(I32="Fail",K32=""),"Classify Issue Source",IF(AND(I32="Fail",W32=""),"Set Confidence",IF(AND(K32="Unknown",W32<>"Low"),"Unknown must be Low confidence",IF(AND(OR(K32="Backend",K32="SAP"),N32=""),"Add HTTP status + endpoint",IF(AND(OR(K32="Backend",K32="SAP",K32="Network"),P32=""),"Add Correlation ID",IF(AND(I32="Fail",T32=""),"Write Root Cause / evidence gap",IF(AND(I32="Fail",V32=""),"Assign team","OK"))))))))
A33: UAT-R1 | B33: TC-AUTH-010 | I33: Not Run | Y33: =IF(I33="","",IF(AND(I33="Fail",K33=""),"Classify Issue Source",IF(AND(I33="Fail",W33=""),"Set Confidence",IF(AND(K33="Unknown",W33<>"Low"),"Unknown must be Low confidence",IF(AND(OR(K33="Backend",K33="SAP"),N33=""),"Add HTTP status + endpoint",IF(AND(OR(K33="Backend",K33="SAP",K33="Network"),P33=""),"Add Correlation ID",IF(AND(I33="Fail",T33=""),"Write Root Cause / evidence gap",IF(AND(I33="Fail",V33=""),"Assign team","OK"))))))))
A34: UAT-R1 | B34: TC-AUTH-011 | I34: Not Run | Y34: =IF(I34="","",IF(AND(I34="Fail",K34=""),"Classify Issue Source",IF(AND(I34="Fail",W34=""),"Set Confidence",IF(AND(K34="Unknown",W34<>"Low"),"Unknown must be Low confidence",IF(AND(OR(K34="Backend",K34="SAP"),N34=""),"Add HTTP status + endpoint",IF(AND(OR(K34="Backend",K34="SAP",K34="Network"),P34=""),"Add Correlation ID",IF(AND(I34="Fail",T34=""),"Write Root Cause / evidence gap",IF(AND(I34="Fail",V34=""),"Assign team","OK"))))))))
A35: UAT-R1 | B35: TC-AUTH-012 | I35: Not Run | Y35: =IF(I35="","",IF(AND(I35="Fail",K35=""),"Classify Issue Source",IF(AND(I35="Fail",W35=""),"Set Confidence",IF(AND(K35="Unknown",W35<>"Low"),"Unknown must be Low confidence",IF(AND(OR(K35="Backend",K35="SAP"),N35=""),"Add HTTP status + endpoint",IF(AND(OR(K35="Backend",K35="SAP",K35="Network"),P35=""),"Add Correlation ID",IF(AND(I35="Fail",T35=""),"Write Root Cause / evidence gap",IF(AND(I35="Fail",V35=""),"Assign team","OK"))))))))
... A59: UAT-R1 | B59: TC-PRO-006 | I59: Not Run | Y59: =IF(I59="","",IF(AND(I59="Fail",K59=""),"Classify Issue Source",IF(AND(I59="Fail",W59=""),"Set Confidence",IF(AND(K59="Unknown",W59<>"Low"),"Unknown must be Low confidence",IF(AND(OR(K59="Backend",K59="SAP"),N59=""),"Add HTTP status + endpoint",IF(AND(OR(K59="Backend",K59="SAP",K59="Network"),P59=""),"Add Correlation ID",IF(AND(I59="Fail",T59=""),"Write Root Cause / evidence gap",IF(AND(I59="Fail",V59=""),"Assign team","OK"))))))))
A60: EXEC-20261008-014 | B60: TC-AUTH-002 | C60: 2026-10-08 | D60: automation (API, device, flutter test) | E60: Staging | F60: 1.0.0+1 @ uat @ a2de10d (modified) | G60: iPhone 17 Pro Max | H60: iOS 26.5 (simulator) | I60: Pass | J60: No | R60: login_no_otp_test.dart: 2 passed; auth_me_profile_test.dart: 5 passed; login_device_test.dart: 1 passed; Screenshots: screenshots/integration_test_auth_login_device_test_dart/after-sign-in.png, screenshots/integration_test_auth_login_device_test_dart/login-screen.png | S60: test_auth.py::test_login_returns_a_usable_token_pair: 1 passed; test_auth.py::test_current_user_matches_the_contract: 1 passed | X60: Automated part only — a manual UAT run is still required. Evidence to Capture: 4 of 4 captured. Evidence: reports/EXEC-20261008-014/cases/TC-AUTH-002/evidence.html | Y60: =IF(I60="","",IF(AND(I60="Fail",K60=""),"Classify Issue Source",IF(AND(I60="Fail",W60=""),"Set Confidence",IF(AND(K60="Unknown",W60<>"Low"),"Unknown must be Low confidence",IF(AND(OR(K60="Backend",K60="SAP"),N60=""),"Add HTTP status + endpoint",IF(AND(OR(K60="Backend",K60="SAP",K60="Network"),P60=""),"Add Correlation ID",IF(AND(I60="Fail",T60=""),"Write Root Cause / evidence gap",IF(AND(I60="Fail",V60=""),"Assign team","OK"))))))))
A61: EXEC-20261008-014 | B61: TC-AUTH-003 | C61: 2026-10-08 | D61: automation (flutter test) | E61: Local (unit/widget) | F61: 1.0.0+1 @ uat @ a2de10d (modified) | G61: host (no device) | H61: n/a | I61: Pass | J61: No | R61: login_screen_layout_test.dart: 15 passed; login_keyboard_test.dart: 3 passed; login_keyboard_insets_test.dart: 2 passed | X61: Evidence to Capture: 3 of 4 captured; missing: Screenshot (EN + KM where text changes). Evidence: reports/EXEC-20261008-014/cases/TC-AUTH-003/evidence.html | Y61: =IF(I61="","",IF(AND(I61="Fail",K61=""),"Classify Issue Source",IF(AND(I61="Fail",W61=""),"Set Confidence",IF(AND(K61="Unknown",W61<>"Low"),"Unknown must be Low confidence",IF(AND(OR(K61="Backend",K61="SAP"),N61=""),"Add HTTP status + endpoint",IF(AND(OR(K61="Backend",K61="SAP",K61="Network"),P61=""),"Add Correlation ID",IF(AND(I61="Fail",T61=""),"Write Root Cause / evidence gap",IF(AND(I61="Fail",V61=""),"Assign team","OK"))))))))
